<sdf version='1.6'>
  <world name='default'>
    <light name='sun' type='directional'>
      <cast_shadows>1</cast_shadows>
      <pose frame=''>0 0 10 0 -0 0</pose>
      <diffuse>0.8 0.8 0.8 1</diffuse>
      <specular>0.1 0.1 0.1 1</specular>
      <attenuation>
        <range>1000</range>
        <constant>0.9</constant>
        <linear>0.01</linear>
        <quadratic>0.001</quadratic>
      </attenuation>
      <direction>-0.5 0.5 -1</direction>
    </light>
    <model name='ground_plane'>
      <static>1</static>
      <link name='link'>
        <collision name='collision'>
          <geometry>
            <plane>
              <normal>0 0 1</normal>
              <size>100 100</size>
            </plane>
          </geometry>
          <surface>
            <friction>
              <ode>
                <mu>100</mu>
                <mu2>50</mu2>
              </ode>
              <torsional>
                <ode/>
              </torsional>
            </friction>
            <contact>
              <ode/>
            </contact>
            <bounce/>
          </surface>
          <max_contacts>10</max_contacts>
        </collision>
        <visual name='visual'>
          <cast_shadows>0</cast_shadows>
          <geometry>
            <plane>
              <normal>0 0 1</normal>
              <size>100 100</size>
            </plane>
          </geometry>
          <material>
            <script>
              <uri>file://media/materials/scripts/gazebo.material</uri>
              <name>Gazebo/Grey</name>
            </script>
          </material>
        </visual>
        <self_collide>0</self_collide>
        <kinematic>0</kinematic>
        <gravity>1</gravity>
      </link>
    </model>
    <gravity>0 0 -9.8</gravity>
    <magnetic_field>6e-06 2.3e-05 -4.2e-05</magnetic_field>
    <atmosphere type='adiabatic'/>
    <physics name='default_physics' default='0' type='ode'>
      <max_step_size>0.001</max_step_size>
      <real_time_factor>1</real_time_factor>
      <real_time_update_rate>1000</real_time_update_rate>
    </physics>
    <scene>
      <ambient>0.4 0.4 0.4 1</ambient>
      <background>0.7 0.7 0.7 1</background>
      <shadows>1</shadows>
    </scene>
    <spherical_coordinates>
      <surface_model>EARTH_WGS84</surface_model>
      <latitude_deg>0</latitude_deg>
      <longitude_deg>0</longitude_deg>
      <elevation>0</elevation>
      <heading_deg>0</heading_deg>
    </spherical_coordinates>
    <state world_name='default'>
      <sim_time>1132 649000000</sim_time>
      <real_time>53 367786686</real_time>
      <wall_time>1554445785 784620033</wall_time>
      <iterations>52982</iterations>
      <model name='cafe_table'>
        <pose frame=''>3.0161 0.016026 0 0 -0 0</pose>
        <scale>1 1 1</scale>
        <link name='link'>
          <pose frame=''>3.0161 0.016026 0 0 -0 0</pose>
          <velocity>0 0 0 0 -0 0</velocity>
          <acceleration>0 0 0 0 -0 0</acceleration>
          <wrench>0 0 0 0 -0 0</wrench>
        </link>
      </model>
      <model name='ground_plane'>
        <pose frame=''>0 0 0 0 -0 0</pose>
        <scale>1 1 1</scale>
        <link name='link'>
          <pose frame=''>0 0 0 0 -0 0</pose>
          <velocity>0 0 0 0 -0 0</velocity>
          <acceleration>0 0 0 0 -0 0</acceleration>
          <wrench>0 0 0 0 -0 0</wrench>
        </link>
      </model>
      <model name='kr210'>
        <pose frame=''>0.028228 0.00393 -2e-06 3e-06 -4e-06 -0.001891</pose>
        <scale>1 1 1</scale>
        <link name='base_footprint'>
          <pose frame=''>0.028228 0.00393 -2e-06 3e-06 -4e-06 -0.001891</pose>
          <velocity>0 -2e-06 -0.002044 -0.000455 -0.004568 4e-06</velocity>
          <acceleration>-0.16041 0.07913 -2.22039 1.54169 0.289733 2.7658</acceleration>
          <wrench>-24.0615 11.8694 -333.059 0 -0 0</wrench>
        </link>
        <link name='left_gripper_finger_link'>
          <pose frame=''>2.33136 0.072115 1.94599 4e-06 4e-06 -0.001892</pose>
          <velocity>-0.000308 -0.000199 -0.005773 -0.000365 0.002902 1.8e-05</velocity>
          <acceleration>-0.308227 -0.199371 -5.77294 2.78167 0.245951 -3.12341</acceleration>
          <wrench>-0.030823 -0.019937 -0.577294 0 -0 0</wrench>
        </link>
        <link name='link_1'>
          <pose frame=''>0.028227 0.003929 0.329998 3e-06 -4e-06 -0.001892</pose>
          <velocity>-0.001553 0.000121 -0.002047 -0.000437 -0.004601 -4e-06</velocity>
          <acceleration>-3.3932 0.295178 -2.04724 2.71079 1.4594 3.13717</acceleration>
          <wrench>-468.262 40.7345 -282.52 0 -0 0</wrench>
        </link>
        <link name='link_2'>
          <pose frame=''>0.378225 0.003265 0.75 4e-06 3e-06 -0.001892</pose>
          <velocity>-0.003503 0.000286 -0.000435 -0.0004 0.002694 -9e-06</velocity>
          <acceleration>-2.29735 0.465563 -0.435117 2.74139 0.447735 3.13256</acceleration>
          <wrench>-218.248 44.2285 -41.3361 0 -0 0</wrench>
        </link>
        <link name='link_3'>
          <pose frame=''>0.378229 0.003261 2 4e-06 3e-06 -0.001892</pose>
          <velocity>-0.000144 0.000768 -0.000437 -0.000385 0.002695 -2.1e-05</velocity>
          <acceleration>-0.25596 0.747677 -1.01654 2.71066 0.446183 3.12108</acceleration>
          <wrench>-18.1732 53.0851 -72.1741 0 -0 0</wrench>
        </link>
        <link name='link_4'>
          <pose frame=''>1.33823 0.001444 1.946 4e-06 3e-06 -0.001892</pose>
          <velocity>-0.000294 0.000695 -0.003035 -0.000373 0.002694 -1.8e-05</velocity>
          <acceleration>-0.294533 0.690035 -3.76284 2.75834 0.447514 3.12313</acceleration>
          <wrench>-5.00705 11.7306 -63.9682 0 -0 0</wrench>
        </link>
        <link name='link_5'>
          <pose frame=''>1.87823 0.000423 1.94599 4e-06 3e-06 -0.001892</pose>
          <velocity>-0.000299 0.000675 -0.004493 -0.000371 0.002704 -3.5e-05</velocity>
          <acceleration>-0.299324 0.674609 -4.49258 2.76692 0.436919 3.10624</acceleration>
          <wrench>-2.09526 4.72226 -31.448 0 -0 0</wrench>
        </link>
        <link name='link_6'>
          <pose frame=''>2.07123 5.8e-05 1.94599 4e-06 3e-06 -0.001892</pose>
          <velocity>-0.000303 0.000659 -0.00502 -0.000367 0.002705 -4.4e-05</velocity>
          <acceleration>-0.30313 0.657044 -5.13112 2.77316 0.436611 3.09769</acceleration>
          <wrench>-0.242504 0.525635 -4.1049 0 -0 0</wrench>
        </link>
        <link name='right_gripper_finger_link'>
          <pose frame=''>2.33109 -0.072884 1.94599 4e-06 4e-06 -0.001892</pose>
          <velocity>-0.000315 -0.000199 -0.005712 -0.000356 0.002875 -0.000119</velocity>
          <acceleration>-0.314642 -0.199359 -5.71159 2.7904 0.272637 3.02285</acceleration>
          <wrench>-0.031464 -0.019936 -0.571159 0 -0 0</wrench>
        </link>
      </model>
      <light name='sun'>
        <pose frame=''>0 0 10 0 -0 0</pose>
      </light>
    </state>
    <gui fullscreen='0'>
      <camera name='user_camera'>
        <pose frame=''>6.54052 6.74405 6.6103 -0 0.831643 -2.44863</pose>
        <view_controller>orbit</view_controller>
        <projection_type>perspective</projection_type>
      </camera>
    </gui>
    <model name='kr210'>
      <link name='base_footprint'>
        <pose frame=''>0 0 0 0 -0 0</pose>
        <inertial>
          <pose frame=''>0 0 0 0 -0 0</pose>
          <mass>150</mass>
          <inertia>
            <ixx>60</ixx>
            <ixy>0</ixy>
            <ixz>0</ixz>
            <iyy>70</iyy>
            <iyz>0</iyz>
            <izz>100</izz>
          </inertia>
        </inertial>
        <collision name='base_footprint_fixed_joint_lump__base_link_collision'>
          <pose frame=''>0 0 0 -1.5708 0 0</pose>
          <geometry>
            <mesh>
              <scale>1 1 1</scale>
              <uri>/home/mxp/catkin_ws/src/pick_and_place/kuka_arm/meshes/kr210l150/collision/base_link.stl</uri>
            </mesh>
          </geometry>
          <surface>
            <contact>
              <ode/>
            </contact>
            <friction>
              <ode>
                <mu>2</mu>
                <mu2>2</mu2>
              </ode>
              <torsional>
                <ode/>
              </torsional>
            </friction>
            <bounce/>
          </surface>
          <max_contacts>10</max_contacts>
        </collision>
        <visual name='base_footprint_fixed_joint_lump__base_link_visual'>
          <pose frame=''>0 0 0 -1.5708 0 0</pose>
          <geometry>
            <mesh>
              <scale>1 1 1</scale>
              <uri>/home/mxp/catkin_ws/src/pick_and_place/kuka_arm/meshes/kr210l150/visual/base_link.dae</uri>
            </mesh>
          </geometry>
          <material>
            <script>
              <name>Gazebo/Grey</name>
              <uri>file://media/materials/scripts/gazebo.material</uri>
            </script>
          </material>
        </visual>
        <gravity>1</gravity>
        <velocity_decay/>
        <self_collide>0</self_collide>
        <kinematic>0</kinematic>
      </link>
      <link name='link_1'>
        <pose frame=''>0 0 0.33 0 -0 0</pose>
        <inertial>
          <pose frame=''>0 0 0.4 0 -0 0</pose>
          <mass>138</mass>
          <inertia>
            <ixx>30</ixx>
            <ixy>0</ixy>
            <ixz>0</ixz>
            <iyy>50</iyy>
            <iyz>0</iyz>
            <izz>50</izz>
          </inertia>
        </inertial>
        <collision name='link_1_collision'>
          <pose frame=''>0 0 0 0 -0 0</pose>
          <geometry>
            <mesh>
              <scale>1 1 1</scale>
              <uri>/home/mxp/catkin_ws/src/pick_and_place/kuka_arm/meshes/kr210l150/collision/link_1.stl</uri>
            </mesh>
          </geometry>
          <surface>
            <contact>
              <ode/>
            </contact>
            <friction>
              <ode>
                <mu>0.2</mu>
                <mu2>0.2</mu2>
              </ode>
              <torsional>
                <ode/>
              </torsional>
            </friction>
            <bounce/>
          </surface>
          <max_contacts>10</max_contacts>
        </collision>
        <visual name='link_1_visual'>
          <pose frame=''>0 0 0 0 -0 0</pose>
          <geometry>
            <mesh>
              <scale>1 1 1</scale>
              <uri>/home/mxp/catkin_ws/src/pick_and_place/kuka_arm/meshes/kr210l150/visual/link_1.dae</uri>
            </mesh>
          </geometry>
          <material>
            <script>
              <uri>__default__</uri>
              <name>__default__</name>
            </script>
          </material>
        </visual>
        <gravity>1</gravity>
        <velocity_decay/>
        <self_collide>0</self_collide>
        <kinematic>0</kinematic>
      </link>
      <joint name='joint_1' type='revolute'>
        <child>link_1</child>
        <parent>base_footprint</parent>
        <axis>
          <xyz>0 0 1</xyz>
          <limit>
            <lower>-3.22886</lower>
            <upper>3.22886</upper>
            <effort>300</effort>
            <velocity>2.14676</velocity>
          </limit>
          <dynamics>
            <spring_reference>0</spring_reference>
            <spring_stiffness>0</spring_stiffness>
          </dynamics>
          <use_parent_model_frame>1</use_parent_model_frame>
        </axis>
      </joint>
      <link name='link_2'>
        <pose frame=''>0.35 0 0.75 0 -0 0</pose>
        <inertial>
          <pose frame=''>0 0 0.44751 0 -0 0</pose>
          <mass>95</mass>
          <inertia>
            <ixx>40</ixx>
            <ixy>0</ixy>
            <ixz>0</ixz>
            <iyy>40</iyy>
            <iyz>0</iyz>
            <izz>10</izz>
          </inertia>
        </inertial>
        <collision name='link_2_collision'>
          <pose frame=''>0 0 0 0 -0 0</pose>
          <geometry>
            <mesh>
              <scale>1 1 1</scale>
              <uri>/home/mxp/catkin_ws/src/pick_and_place/kuka_arm/meshes/kr210l150/collision/link_2.stl</uri>
            </mesh>
          </geometry>
          <surface>
            <contact>
              <ode/>
            </contact>
            <friction>
              <ode>
                <mu>0.2</mu>
                <mu2>0.2</mu2>
              </ode>
              <torsional>
                <ode/>
              </torsional>
            </friction>
            <bounce/>
          </surface>
          <max_contacts>10</max_contacts>
        </collision>
        <visual name='link_2_visual'>
          <pose frame=''>0 0 0 -1.5708 0 0</pose>
          <geometry>
            <mesh>
              <scale>1 1 1</scale>
              <uri>/home/mxp/catkin_ws/src/pick_and_place/kuka_arm/meshes/kr210l150/visual/link_2.dae</uri>
            </mesh>
          </geometry>
          <material>
            <script>
              <uri>__default__</uri>
              <name>__default__</name>
            </script>
          </material>
        </visual>
        <gravity>1</gravity>
        <velocity_decay/>
        <self_collide>0</self_collide>
        <kinematic>0</kinematic>
      </link>
      <joint name='joint_2' type='revolute'>
        <child>link_2</child>
        <parent>link_1</parent>
        <axis>
          <xyz>0 1 0</xyz>
          <limit>
            <lower>-0.785398</lower>
            <upper>1.48353</upper>
            <effort>300</effort>
            <velocity>2.00713</velocity>
          </limit>
          <dynamics>
            <spring_reference>0</spring_reference>
            <spring_stiffness>0</spring_stiffness>
          </dynamics>
          <use_parent_model_frame>1</use_parent_model_frame>
        </axis>
      </joint>
      <link name='link_3'>
        <pose frame=''>0.35 0 2 0 -0 0</pose>
        <inertial>
          <pose frame=''>0.18842 0.18344 -0.042799 0 -0 0</pose>
          <mass>71</mass>
          <inertia>
            <ixx>1</ixx>
            <ixy>0</ixy>
            <ixz>0</ixz>
            <iyy>10</iyy>
            <iyz>0</iyz>
            <izz>10</izz>
          </inertia>
        </inertial>
        <collision name='link_3_collision'>
          <pose frame=''>0 -0.184 0 0 -0 0</pose>
          <geometry>
            <mesh>
              <scale>1 1 1</scale>
              <uri>/home/mxp/catkin_ws/src/pick_and_place/kuka_arm/meshes/kr210l150/collision/link_3.stl</uri>
            </mesh>
          </geometry>
          <surface>
            <contact>
              <ode/>
            </contact>
            <friction>
              <ode>
                <mu>0.2</mu>
                <mu2>0.2</mu2>
              </ode>
              <torsional>
                <ode/>
              </torsional>
            </friction>
            <bounce/>
          </surface>
          <max_contacts>10</max_contacts>
        </collision>
        <visual name='link_3_visual'>
          <pose frame=''>0 -0.184 0 -1.5708 0 0</pose>
          <geometry>
            <mesh>
              <scale>1 1 1</scale>
              <uri>/home/mxp/catkin_ws/src/pick_and_place/kuka_arm/meshes/kr210l150/visual/link_3.dae</uri>
            </mesh>
          </geometry>
          <material>
            <script>
              <uri>__default__</uri>
              <name>__default__</name>
            </script>
          </material>
        </visual>
        <gravity>1</gravity>
        <velocity_decay/>
        <self_collide>0</self_collide>
        <kinematic>0</kinematic>
      </link>
      <joint name='joint_3' type='revolute'>
        <child>link_3</child>
        <parent>link_2</parent>
        <axis>
          <xyz>0 1 0</xyz>
          <limit>
            <lower>-3.66519</lower>
            <upper>1.13446</upper>
            <effort>300</effort>
            <velocity>1.95477</velocity>
          </limit>
          <dynamics>
            <spring_reference>0</spring_reference>
            <spring_stiffness>0</spring_stiffness>
          </dynamics>
          <use_parent_model_frame>1</use_parent_model_frame>
        </axis>
      </joint>
      <link name='link_4'>
        <pose frame=''>1.31 0 1.946 0 -0 0</pose>
        <inertial>
          <pose frame=''>0.27146 -0.007326 0 0 -0 0</pose>
          <mass>17</mass>
          <inertia>
            <ixx>0.18</ixx>
            <ixy>0</ixy>
            <ixz>0</ixz>
            <iyy>0.55</iyy>
            <iyz>0</iyz>
            <izz>0.64</izz>
          </inertia>
        </inertial>
        <collision name='link_4_collision'>
          <pose frame=''>0 0 0 0 -0 0</pose>
          <geometry>
            <mesh>
              <scale>1 1 1</scale>
              <uri>/home/mxp/catkin_ws/src/pick_and_place/kuka_arm/meshes/kr210l150/collision/link_4.stl</uri>
            </mesh>
          </geometry>
          <surface>
            <contact>
              <ode/>
            </contact>
            <friction>
              <ode>
                <mu>0.2</mu>
                <mu2>0.2</mu2>
              </ode>
              <torsional>
                <ode/>
              </torsional>
            </friction>
            <bounce/>
          </surface>
          <max_contacts>10</max_contacts>
        </collision>
        <visual name='link_4_visual'>
          <pose frame=''>0 0 0 -1.5708 0 0</pose>
          <geometry>
            <mesh>
              <scale>1 1 1</scale>
              <uri>/home/mxp/catkin_ws/src/pick_and_place/kuka_arm/meshes/kr210l150/visual/link_4.dae</uri>
            </mesh>
          </geometry>
          <material>
            <script>
              <uri>__default__</uri>
              <name>__default__</name>
            </script>
          </material>
        </visual>
        <gravity>1</gravity>
        <velocity_decay/>
        <self_collide>0</self_collide>
        <kinematic>0</kinematic>
      </link>
      <joint name='joint_4' type='revolute'>
        <child>link_4</child>
        <parent>link_3</parent>
        <axis>
          <xyz>1 0 0</xyz>
          <limit>
            <lower>-6.10865</lower>
            <upper>6.10865</upper>
            <effort>300</effort>
            <velocity>3.12414</velocity>
          </limit>
          <dynamics>
            <spring_reference>0</spring_reference>
            <spring_stiffness>0</spring_stiffness>
          </dynamics>
          <use_parent_model_frame>1</use_parent_model_frame>
        </axis>
      </joint>
      <link name='link_5'>
        <pose frame=''>1.85 0 1.946 0 -0 0</pose>
        <inertial>
          <pose frame=''>0 0 0 0 -0 0</pose>
          <mass>7</mass>
          <inertia>
            <ixx>0.04</ixx>
            <ixy>0</ixy>
            <ixz>0</ixz>
            <iyy>0.068</iyy>
            <iyz>0</iyz>
            <izz>0.068</izz>
          </inertia>
        </inertial>
        <collision name='link_5_collision'>
          <pose frame=''>0 0 0 0 -0 0</pose>
          <geometry>
            <mesh>
              <scale>1 1 1</scale>
              <uri>/home/mxp/catkin_ws/src/pick_and_place/kuka_arm/meshes/kr210l150/collision/link_5.stl</uri>
            </mesh>
          </geometry>
          <surface>
            <contact>
              <ode/>
            </contact>
            <friction>
              <ode>
                <mu>0.2</mu>
                <mu2>0.2</mu2>
              </ode>
              <torsional>
                <ode/>
              </torsional>
            </friction>
            <bounce/>
          </surface>
          <max_contacts>10</max_contacts>
        </collision>
        <visual name='link_5_visual'>
          <pose frame=''>0 0 0 -1.5708 0 0</pose>
          <geometry>
            <mesh>
              <scale>1 1 1</scale>
              <uri>/home/mxp/catkin_ws/src/pick_and_place/kuka_arm/meshes/kr210l150/visual/link_5.dae</uri>
            </mesh>
          </geometry>
          <material>
            <script>
              <uri>__default__</uri>
              <name>__default__</name>
            </script>
          </material>
        </visual>
        <gravity>1</gravity>
        <velocity_decay/>
        <self_collide>0</self_collide>
        <kinematic>0</kinematic>
      </link>
      <joint name='joint_5' type='revolute'>
        <child>link_5</child>
        <parent>link_4</parent>
        <axis>
          <xyz>0 1 0</xyz>
          <limit>
            <lower>-2.18166</lower>
            <upper>2.18166</upper>
            <effort>300</effort>
            <velocity>3.00197</velocity>
          </limit>
          <dynamics>
            <spring_reference>0</spring_reference>
            <spring_stiffness>0</spring_stiffness>
          </dynamics>
          <use_parent_model_frame>1</use_parent_model_frame>
        </axis>
      </joint>
      <link name='link_6'>
        <pose frame=''>2.043 0 1.946 0 -0 0</pose>
        <inertial>
          <pose frame=''>0.04125 0 0 0 -0 0</pose>
          <mass>0.8</mass>
          <inertia>
            <ixx>0.0041</ixx>
            <ixy>0</ixy>
            <ixz>0</ixz>
            <iyy>0.00546875</iyy>
            <iyz>0</iyz>
            <izz>0.00536875</izz>
          </inertia>
        </inertial>
        <collision name='link_6_collision'>
          <pose frame=''>0 0 0 0 -0 0</pose>
          <geometry>
            <mesh>
              <scale>1 1 1</scale>
              <uri>/home/mxp/catkin_ws/src/pick_and_place/kuka_arm/meshes/kr210l150/collision/link_6.stl</uri>
            </mesh>
          </geometry>
          <surface>
            <contact>
              <ode/>
            </contact>
            <friction>
              <ode>
                <mu>0.2</mu>
                <mu2>0.2</mu2>
              </ode>
              <torsional>
                <ode/>
              </torsional>
            </friction>
            <bounce/>
          </surface>
          <max_contacts>10</max_contacts>
        </collision>
        <collision name='link_6_fixed_joint_lump__gripper_link_collision_1'>
          <pose frame=''>0.11 0 0 0 -0 0</pose>
          <geometry>
            <mesh>
              <scale>1 1 1</scale>
              <uri>/home/mxp/catkin_ws/src/pick_and_place/kuka_arm/meshes/gripper/gripper_base.dae</uri>
            </mesh>
          </geometry>
          <surface>
            <contact>
              <ode/>
            </contact>
            <friction>
              <ode>
                <mu>0.2</mu>
                <mu2>0.2</mu2>
              </ode>
              <torsional>
                <ode/>
              </torsional>
            </friction>
            <bounce/>
          </surface>
          <max_contacts>10</max_contacts>
        </collision>
        <visual name='link_6_visual'>
          <pose frame=''>0 0 0 0 -0 0</pose>
          <geometry>
            <mesh>
              <scale>1 1 1</scale>
              <uri>/home/mxp/catkin_ws/src/pick_and_place/kuka_arm/meshes/kr210l150/visual/link_6.dae</uri>
            </mesh>
          </geometry>
          <material>
            <script>
              <uri>__default__</uri>
              <name>__default__</name>
            </script>
          </material>
        </visual>
        <visual name='link_6_fixed_joint_lump__gripper_link_visual_1'>
          <pose frame=''>0.11 0 0 0 -0 0</pose>
          <geometry>
            <mesh>
              <scale>1 1 1</scale>
              <uri>/home/mxp/catkin_ws/src/pick_and_place/kuka_arm/meshes/gripper/gripper_base.dae</uri>
            </mesh>
          </geometry>
          <material>
            <script>
              <name>Gazebo/Grey</name>
              <uri>file://media/materials/scripts/gazebo.material</uri>
            </script>
          </material>
        </visual>
        <velocity_decay/>
        <gravity>1</gravity>
        <velocity_decay/>
        <self_collide>0</self_collide>
        <kinematic>0</kinematic>
      </link>
      <joint name='joint_6' type='revolute'>
        <child>link_6</child>
        <parent>link_5</parent>
        <axis>
          <xyz>1 0 0</xyz>
          <limit>
            <lower>-6.10865</lower>
            <upper>6.10865</upper>
            <effort>300</effort>
            <velocity>3.82227</velocity>
          </limit>
          <dynamics>
            <spring_reference>0</spring_reference>
            <spring_stiffness>0</spring_stiffness>
          </dynamics>
          <use_parent_model_frame>1</use_parent_model_frame>
        </axis>
      </joint>
      <link name='left_gripper_finger_link'>
        <pose frame=''>2.303 0.0725 1.946 0 -0 0</pose>
        <inertial>
          <pose frame=''>0 0 0 0 -0 0</pose>
          <mass>0.1</mass>
          <inertia>
            <ixx>0.002</ixx>
            <ixy>0</ixy>
            <ixz>0</ixz>
            <iyy>0.0002</iyy>
            <iyz>0</iyz>
            <izz>0.0002</izz>
          </inertia>
        </inertial>
        <collision name='left_gripper_finger_link_collision'>
          <pose frame=''>0 0 0 0 -0 0</pose>
          <geometry>
            <mesh>
              <scale>1 1 1</scale>
              <uri>/home/mxp/catkin_ws/src/pick_and_place/kuka_arm/meshes/gripper/finger_left_collision.dae</uri>
            </mesh>
          </geometry>
          <surface>
            <contact>
              <ode>
                <kp>1e+06</kp>
                <kd>1</kd>
              </ode>
            </contact>
            <friction>
              <ode>
                <mu>30</mu>
                <mu2>30</mu2>
              </ode>
              <torsional>
                <ode/>
              </torsional>
            </friction>
            <bounce/>
          </surface>
          <max_contacts>10</max_contacts>
        </collision>
        <visual name='left_gripper_finger_link_visual'>
          <pose frame=''>0 0 0 0 -0 0</pose>
          <geometry>
            <mesh>
              <scale>1 1 1</scale>
              <uri>/home/mxp/catkin_ws/src/pick_and_place/kuka_arm/meshes/gripper/finger_left.dae</uri>
            </mesh>
          </geometry>
          <material>
            <script>
              <name>Gazebo/Grey</name>
              <uri>file://media/materials/scripts/gazebo.material</uri>
            </script>
          </material>
        </visual>
        <gravity>1</gravity>
        <velocity_decay/>
        <self_collide>0</self_collide>
        <kinematic>0</kinematic>
      </link>
      <joint name='left_gripper_finger_joint' type='prismatic'>
        <child>left_gripper_finger_link</child>
        <parent>link_6</parent>
        <axis>
          <xyz>0 -1 0</xyz>
          <limit>
            <lower>-0.01</lower>
            <upper>0.06</upper>
            <effort>100</effort>
            <velocity>0.05</velocity>
          </limit>
          <dynamics>
            <damping>0.7</damping>
            <friction>0</friction>
            <spring_reference>0</spring_reference>
            <spring_stiffness>0</spring_stiffness>
          </dynamics>
          <use_parent_model_frame>1</use_parent_model_frame>
        </axis>
      </joint>
      <link name='right_gripper_finger_link'>
        <pose frame=''>2.303 -0.0725 1.946 0 -0 0</pose>
        <inertial>
          <pose frame=''>0 0 0 0 -0 0</pose>
          <mass>0.1</mass>
          <inertia>
            <ixx>0.002</ixx>
            <ixy>0</ixy>
            <ixz>0</ixz>
            <iyy>0.0002</iyy>
            <iyz>0</iyz>
            <izz>0.0002</izz>
          </inertia>
        </inertial>
        <collision name='right_gripper_finger_link_collision'>
          <pose frame=''>0 0 0 0 -0 0</pose>
          <geometry>
            <mesh>
              <scale>1 1 1</scale>
              <uri>/home/mxp/catkin_ws/src/pick_and_place/kuka_arm/meshes/gripper/finger_right_collision.dae</uri>
            </mesh>
          </geometry>
          <surface>
            <contact>
              <ode>
                <kp>1e+06</kp>
                <kd>1</kd>
              </ode>
            </contact>
            <friction>
              <ode>
                <mu>30</mu>
                <mu2>30</mu2>
              </ode>
              <torsional>
                <ode/>
              </torsional>
            </friction>
            <bounce/>
          </surface>
          <max_contacts>10</max_contacts>
        </collision>
        <visual name='right_gripper_finger_link_visual'>
          <pose frame=''>0 0 0 0 -0 0</pose>
          <geometry>
            <mesh>
              <scale>1 1 1</scale>
              <uri>/home/mxp/catkin_ws/src/pick_and_place/kuka_arm/meshes/gripper/finger_right.dae</uri>
            </mesh>
          </geometry>
          <material>
            <script>
              <name>Gazebo/Grey</name>
              <uri>file://media/materials/scripts/gazebo.material</uri>
            </script>
          </material>
        </visual>
        <gravity>1</gravity>
        <velocity_decay/>
        <self_collide>0</self_collide>
        <kinematic>0</kinematic>
      </link>
      <joint name='right_gripper_finger_joint' type='prismatic'>
        <child>right_gripper_finger_link</child>
        <parent>link_6</parent>
        <axis>
          <xyz>0 1 0</xyz>
          <limit>
            <lower>-0.01</lower>
            <upper>0.06</upper>
            <effort>100</effort>
            <velocity>0.05</velocity>
          </limit>
          <dynamics>
            <damping>0.7</damping>
            <friction>0</friction>
            <spring_reference>0</spring_reference>
            <spring_stiffness>0</spring_stiffness>
          </dynamics>
          <use_parent_model_frame>1</use_parent_model_frame>
        </axis>
      </joint>
      <plugin name='gazebo_ros_control' filename='libgazebo_ros_control.so'>
        <robotNamespace>/kuka_arm</robotNamespace>
        <robotSimType>gazebo_ros_control/DefaultRobotHWSim</robotSimType>
      </plugin>
      <static>0</static>
      <plugin name='gazebo_grasp_fix' filename='libgazebo_grasp_fix.so'>
        <arm>
          <arm_name>kuka_arm</arm_name>
          <palm_link>link_6</palm_link>
          <gripper_link>right_gripper_finger_link</gripper_link>
          <gripper_link>left_gripper_finger_link</gripper_link>
        </arm>
        <forces_angle_tolerance>100</forces_angle_tolerance>
        <update_rate>4</update_rate>
        <grip_count_threshold>4</grip_count_threshold>
        <max_grip_count>8</max_grip_count>
        <release_tolerance>0.003</release_tolerance>
        <disable_collisions_on_attach>false</disable_collisions_on_attach>
        <contact_topic>__default_topic__</contact_topic>
        <robotNamespace>/</robotNamespace>
      </plugin>
      <pose frame=''>0 0 0.2 0 -0 0</pose>
    </model>


  </world>
</sdf>
